{"uuid": "0eb575b5-c0b0-4237-ac19-b3306ed43bc5", "children": ["0ecdd21f-275d-47d7-8c3a-5a4229b979de"], "befores": [{"name": "start_function_App_and_launcher_name", "status": "broken", "statusDetails": {"message": "selenium.common.exceptions.WebDriverException: Message: An unknown server-side error occurred while processing the command. Original error: Error executing adbExec. Original error: 'Command 'D:\\\\Android\\\\android-sdk-windows\\\\platform-tools\\\\adb.exe -P 5037 -s e855dee1 shell pm clear com.duixivideo.app' exited with code 1'; Command output: Error: java.lang.SecurityException: PID 22698 does not have permission android.permission.CLEAR_APP_USER_DATA to clear data of package com.duixivideo.app\r\n\n\n", "trace": "  File \"d:\\python\\python38\\lib\\site-packages\\pluggy\\callers.py\", line 187, in _multicall\n    res = hook_impl.function(*args)\n  File \"d:\\python\\python38\\lib\\site-packages\\_pytest\\fixtures.py\", line 957, in pytest_fixture_setup\n    result = call_fixture_func(fixturefunc, request, kwargs)\n  File \"d:\\python\\python38\\lib\\site-packages\\_pytest\\fixtures.py\", line 783, in call_fixture_func\n    res = next(it)\n  File \"D:\\JetBrains\\PyCharm\\PycharmProjects\\Duixi_Framework_V1\\TestCases\\Test0Welcome\\conftest.py\", line 58, in start_function_App_and_launcher_name\n    driver = baseDriver(noReset=False)\n  File \"D:\\JetBrains\\PyCharm\\PycharmProjects\\Duixi_Framework_V1\\Common\\base_driver.py\", line 45, in baseDriver\n    driver = webdriver.Remote('http://127.0.0.1:{}/wd/hub'.format(server_port), caps)\n  File \"d:\\python\\python38\\lib\\site-packages\\appium\\webdriver\\webdriver.py\", line 151, in __init__\n    super().__init__(\n  File \"d:\\python\\python38\\lib\\site-packages\\selenium\\webdriver\\remote\\webdriver.py\", line 157, in __init__\n    self.start_session(capabilities, browser_profile)\n  File \"d:\\python\\python38\\lib\\site-packages\\appium\\webdriver\\webdriver.py\", line 225, in start_session\n    response = self.execute(RemoteCommand.NEW_SESSION, parameters)\n  File \"d:\\python\\python38\\lib\\site-packages\\selenium\\webdriver\\remote\\webdriver.py\", line 321, in execute\n    self.error_handler.check_response(response)\n  File \"d:\\python\\python38\\lib\\site-packages\\selenium\\webdriver\\remote\\errorhandler.py\", line 242, in check_response\n    raise exception_class(message, screen, stacktrace)\n"}, "start": 1649597411265, "stop": 1649597419872}], "start": 1649597411265, "stop": 1649597419946}