{"uuid": "681e2f46-bb08-476f-babf-c8dcf758589f", "children": ["0764eb35-1427-45ac-aebe-beeb5f5abd7d", "68d23b8c-be18-41db-89df-edbfa1486364", "a8078c6f-e64a-4bad-aff9-0d3e724f5b6c", "89683038-9d6e-4908-a956-05bf9f68e31d"], "befores": [{"name": "startApp", "status": "broken", "statusDetails": {"message": "urllib3.exceptions.MaxRetryError: HTTPConnectionPool(host='127.0.0.1', port=4723): Max retries exceeded with url: /wd/hub/session (Caused by NewConnectionError('<urllib3.connection.HTTPConnection object at 0x000001B92B7581F0>: Failed to establish a new connection: [WinError 10061] 由于目标计算机积极拒绝，无法连接。'))\n", "trace": "  File \"d:\\python\\python38\\lib\\site-packages\\pluggy\\_callers.py\", line 39, in _multicall\n    res = hook_impl.function(*args)\n  File \"d:\\python\\python38\\lib\\site-packages\\_pytest\\fixtures.py\", line 1122, in pytest_fixture_setup\n    result = call_fixture_func(fixturefunc, request, kwargs)\n  File \"d:\\python\\python38\\lib\\site-packages\\_pytest\\fixtures.py\", line 917, in call_fixture_func\n    fixture_result = next(generator)\n  File \"D:\\JetBrains\\PyCharm\\PycharmProjects\\Duixi_Framework_V1\\TestCases\\Test0Welcome\\conftest.py\", line 33, in startApp\n    driver = baseDriver(noReset=False)\n  File \"D:\\JetBrains\\PyCharm\\PycharmProjects\\Duixi_Framework_V1\\TestCases\\Test0Welcome\\conftest.py\", line 67, in baseDriver\n    driver = webdriver.Remote('http://127.0.0.1:4723/wd/hub', caps)\n  File \"d:\\python\\python38\\lib\\site-packages\\appium\\webdriver\\webdriver.py\", line 151, in __init__\n    super().__init__(\n  File \"d:\\python\\python38\\lib\\site-packages\\selenium\\webdriver\\remote\\webdriver.py\", line 157, in __init__\n    self.start_session(capabilities, browser_profile)\n  File \"d:\\python\\python38\\lib\\site-packages\\appium\\webdriver\\webdriver.py\", line 225, in start_session\n    response = self.execute(RemoteCommand.NEW_SESSION, parameters)\n  File \"d:\\python\\python38\\lib\\site-packages\\selenium\\webdriver\\remote\\webdriver.py\", line 319, in execute\n    response = self.command_executor.execute(driver_command, params)\n  File \"d:\\python\\python38\\lib\\site-packages\\selenium\\webdriver\\remote\\remote_connection.py\", line 376, in execute\n    return self._request(command_info[0], url, body=data)\n  File \"d:\\python\\python38\\lib\\site-packages\\selenium\\webdriver\\remote\\remote_connection.py\", line 399, in _request\n    resp = self._conn.request(method, url, body=body, headers=headers)\n  File \"d:\\python\\python38\\lib\\site-packages\\urllib3\\request.py\", line 78, in request\n    return self.request_encode_body(\n  File \"d:\\python\\python38\\lib\\site-packages\\urllib3\\request.py\", line 170, in request_encode_body\n    return self.urlopen(method, url, **extra_kw)\n  File \"d:\\python\\python38\\lib\\site-packages\\urllib3\\poolmanager.py\", line 375, in urlopen\n    response = conn.urlopen(method, u.request_uri, **kw)\n  File \"d:\\python\\python38\\lib\\site-packages\\urllib3\\connectionpool.py\", line 783, in urlopen\n    return self.urlopen(\n  File \"d:\\python\\python38\\lib\\site-packages\\urllib3\\connectionpool.py\", line 783, in urlopen\n    return self.urlopen(\n  File \"d:\\python\\python38\\lib\\site-packages\\urllib3\\connectionpool.py\", line 783, in urlopen\n    return self.urlopen(\n  File \"d:\\python\\python38\\lib\\site-packages\\urllib3\\connectionpool.py\", line 755, in urlopen\n    retries = retries.increment(\n  File \"d:\\python\\python38\\lib\\site-packages\\urllib3\\util\\retry.py\", line 573, in increment\n    raise MaxRetryError(_pool, url, error or ResponseError(cause))\n"}, "start": 1649166675566, "stop": 1649166680595}], "start": 1649166675566, "stop": 1649166681868}